[2024-01-23T15:49:01.322+0000] {taskinstance.py:1956} INFO - Dependencies all met for dep_context=non-requeueable deps ti=<TaskInstance: execute_python_files_dag.execute_python_file_4 manual__2024-01-23T15:48:34.058554+00:00 [queued]>
[2024-01-23T15:49:01.335+0000] {taskinstance.py:1956} INFO - Dependencies all met for dep_context=requeueable deps ti=<TaskInstance: execute_python_files_dag.execute_python_file_4 manual__2024-01-23T15:48:34.058554+00:00 [queued]>
[2024-01-23T15:49:01.335+0000] {taskinstance.py:2170} INFO - Starting attempt 1 of 1
[2024-01-23T15:49:01.468+0000] {taskinstance.py:2191} INFO - Executing <Task(PythonOperator): execute_python_file_4> on 2024-01-23 15:48:34.058554+00:00
[2024-01-23T15:49:01.473+0000] {standard_task_runner.py:60} INFO - Started process 280 to run task
[2024-01-23T15:49:01.478+0000] {standard_task_runner.py:87} INFO - Running: ['airflow', 'tasks', 'run', 'execute_python_files_dag', 'execute_python_file_4', 'manual__2024-01-23T15:48:34.058554+00:00', '--job-id', '16', '--raw', '--subdir', 'DAGS_FOLDER/etl_dag.py', '--cfg-path', '/tmp/tmp5c7x_8z9']
[2024-01-23T15:49:01.480+0000] {standard_task_runner.py:88} INFO - Job 16: Subtask execute_python_file_4
[2024-01-23T15:49:01.696+0000] {task_command.py:423} INFO - Running <TaskInstance: execute_python_files_dag.execute_python_file_4 manual__2024-01-23T15:48:34.058554+00:00 [running]> on host b977193ffa62
[2024-01-23T15:49:01.937+0000] {taskinstance.py:2480} INFO - Exporting env vars: AIRFLOW_CTX_DAG_OWNER='airflow' AIRFLOW_CTX_DAG_ID='execute_python_files_dag' AIRFLOW_CTX_TASK_ID='execute_python_file_4' AIRFLOW_CTX_EXECUTION_DATE='2024-01-23T15:48:34.058554+00:00' AIRFLOW_CTX_TRY_NUMBER='1' AIRFLOW_CTX_DAG_RUN_ID='manual__2024-01-23T15:48:34.058554+00:00'
[2024-01-23T15:49:01.938+0000] {logging_mixin.py:188} INFO - Error executing file C:\Users\havet\Desktop\workflow_1\load.py: [Errno 2] No such file or directory: 'C:\\Users\\havet\\Desktop\\workflow_1\\load.py'
[2024-01-23T15:49:01.938+0000] {python.py:201} INFO - Done. Returned value was: None
[2024-01-23T15:49:01.950+0000] {taskinstance.py:1138} INFO - Marking task as SUCCESS. dag_id=execute_python_files_dag, task_id=execute_python_file_4, execution_date=20240123T154834, start_date=20240123T154901, end_date=20240123T154901
[2024-01-23T15:49:02.255+0000] {local_task_job_runner.py:234} INFO - Task exited with return code 0
[2024-01-23T15:49:02.275+0000] {taskinstance.py:3280} INFO - 0 downstream tasks scheduled from follow-on schedule check
